2024-03-07 08:33:22 ERROR Traceback (most recent call last):
  File "/home2/surya_ravindra/miniconda3/envs/pytorch_conda/lib/python3.8/site-packages/wandb/apis/normalize.py", line 41, in wrapper
    return func(*args, **kwargs)
  File "/home2/surya_ravindra/miniconda3/envs/pytorch_conda/lib/python3.8/site-packages/wandb/sdk/internal/internal_api.py", line 1065, in sweep
    raise ValueError(f"Sweep {entity}/{project}/{sweep} not found")
ValueError: Sweep sriharib128/CV_A1_Q2/sweep_id not found

During handling of the above exception, another exception occurred:

Traceback (most recent call last):
  File "/home2/surya_ravindra/miniconda3/envs/pytorch_conda/lib/python3.8/site-packages/wandb/cli/cli.py", line 105, in wrapper
    return func(*args, **kwargs)
  File "/home2/surya_ravindra/miniconda3/envs/pytorch_conda/lib/python3.8/site-packages/wandb/cli/cli.py", line 926, in sweep
    getattr(api, "%s_sweep" % state)(sweep_id, entity=entity, project=project)
  File "/home2/surya_ravindra/miniconda3/envs/pytorch_conda/lib/python3.8/site-packages/wandb/apis/internal.py", line 138, in stop_sweep
    return self.api.stop_sweep(*args, **kwargs)
  File "/home2/surya_ravindra/miniconda3/envs/pytorch_conda/lib/python3.8/site-packages/wandb/sdk/internal/internal_api.py", line 4124, in stop_sweep
    self.set_sweep_state(
  File "/home2/surya_ravindra/miniconda3/envs/pytorch_conda/lib/python3.8/site-packages/wandb/sdk/internal/internal_api.py", line 4079, in set_sweep_state
    s = self.sweep(sweep=sweep, entity=entity, project=project, specs="{}")
  File "/home2/surya_ravindra/miniconda3/envs/pytorch_conda/lib/python3.8/site-packages/wandb/apis/normalize.py", line 87, in wrapper
    raise CommError(message, err).with_traceback(sys.exc_info()[2])
  File "/home2/surya_ravindra/miniconda3/envs/pytorch_conda/lib/python3.8/site-packages/wandb/apis/normalize.py", line 41, in wrapper
    return func(*args, **kwargs)
  File "/home2/surya_ravindra/miniconda3/envs/pytorch_conda/lib/python3.8/site-packages/wandb/sdk/internal/internal_api.py", line 1065, in sweep
    raise ValueError(f"Sweep {entity}/{project}/{sweep} not found")
wandb.errors.CommError: Sweep sriharib128/CV_A1_Q2/sweep_id not found

2024-03-07 08:49:05 ERROR Traceback (most recent call last):
  File "/home2/surya_ravindra/miniconda3/envs/pytorch_conda/lib/python3.8/site-packages/wandb/apis/normalize.py", line 41, in wrapper
    return func(*args, **kwargs)
  File "/home2/surya_ravindra/miniconda3/envs/pytorch_conda/lib/python3.8/site-packages/wandb/sdk/internal/internal_api.py", line 2522, in download_urls
    files = self._flatten_edges(query_result["model"]["bucket"]["files"])
TypeError: 'NoneType' object is not subscriptable

During handling of the above exception, another exception occurred:

Traceback (most recent call last):
  File "/home2/surya_ravindra/miniconda3/envs/pytorch_conda/lib/python3.8/site-packages/wandb/cli/cli.py", line 105, in wrapper
    return func(*args, **kwargs)
  File "/home2/surya_ravindra/miniconda3/envs/pytorch_conda/lib/python3.8/site-packages/wandb/cli/cli.py", line 2493, in pull
    urls = api.download_urls(project, run=run, entity=entity)
  File "/home2/surya_ravindra/miniconda3/envs/pytorch_conda/lib/python3.8/site-packages/wandb/apis/internal.py", line 117, in download_urls
    return self.api.download_urls(*args, **kwargs)
  File "/home2/surya_ravindra/miniconda3/envs/pytorch_conda/lib/python3.8/site-packages/wandb/apis/normalize.py", line 87, in wrapper
    raise CommError(message, err).with_traceback(sys.exc_info()[2])
  File "/home2/surya_ravindra/miniconda3/envs/pytorch_conda/lib/python3.8/site-packages/wandb/apis/normalize.py", line 41, in wrapper
    return func(*args, **kwargs)
  File "/home2/surya_ravindra/miniconda3/envs/pytorch_conda/lib/python3.8/site-packages/wandb/sdk/internal/internal_api.py", line 2522, in download_urls
    files = self._flatten_edges(query_result["model"]["bucket"]["files"])
wandb.errors.CommError: 'NoneType' object is not subscriptable

2024-03-07 08:49:54 ERROR Traceback (most recent call last):
  File "/home2/surya_ravindra/miniconda3/envs/pytorch_conda/lib/python3.8/site-packages/wandb/sdk/wandb_manager.py", line 116, in _service_connect
    svc_iface._svc_connect(port=port)
  File "/home2/surya_ravindra/miniconda3/envs/pytorch_conda/lib/python3.8/site-packages/wandb/sdk/service/service_sock.py", line 30, in _svc_connect
    self._sock_client.connect(port=port)
  File "/home2/surya_ravindra/miniconda3/envs/pytorch_conda/lib/python3.8/site-packages/wandb/sdk/lib/sock_client.py", line 102, in connect
    s.connect(("localhost", port))
ConnectionRefusedError: [Errno 111] Connection refused

During handling of the above exception, another exception occurred:

Traceback (most recent call last):
  File "/home2/surya_ravindra/miniconda3/envs/pytorch_conda/lib/python3.8/site-packages/wandb/cli/cli.py", line 105, in wrapper
    return func(*args, **kwargs)
  File "/home2/surya_ravindra/miniconda3/envs/pytorch_conda/lib/python3.8/site-packages/wandb/cli/cli.py", line 244, in login
    wandb.setup(settings=login_settings)
  File "/home2/surya_ravindra/miniconda3/envs/pytorch_conda/lib/python3.8/site-packages/wandb/sdk/wandb_setup.py", line 327, in setup
    ret = _setup(settings=settings)
  File "/home2/surya_ravindra/miniconda3/envs/pytorch_conda/lib/python3.8/site-packages/wandb/sdk/wandb_setup.py", line 320, in _setup
    wl = _WandbSetup(settings=settings)
  File "/home2/surya_ravindra/miniconda3/envs/pytorch_conda/lib/python3.8/site-packages/wandb/sdk/wandb_setup.py", line 303, in __init__
    _WandbSetup._instance = _WandbSetup__WandbSetup(settings=settings, pid=pid)
  File "/home2/surya_ravindra/miniconda3/envs/pytorch_conda/lib/python3.8/site-packages/wandb/sdk/wandb_setup.py", line 114, in __init__
    self._setup()
  File "/home2/surya_ravindra/miniconda3/envs/pytorch_conda/lib/python3.8/site-packages/wandb/sdk/wandb_setup.py", line 250, in _setup
    self._setup_manager()
  File "/home2/surya_ravindra/miniconda3/envs/pytorch_conda/lib/python3.8/site-packages/wandb/sdk/wandb_setup.py", line 277, in _setup_manager
    self._manager = wandb_manager._Manager(settings=self._settings)
  File "/home2/surya_ravindra/miniconda3/envs/pytorch_conda/lib/python3.8/site-packages/wandb/sdk/wandb_manager.py", line 153, in __init__
    wandb._sentry.reraise(e)
  File "/home2/surya_ravindra/miniconda3/envs/pytorch_conda/lib/python3.8/site-packages/wandb/analytics/sentry.py", line 154, in reraise
    raise exc.with_traceback(sys.exc_info()[2])
  File "/home2/surya_ravindra/miniconda3/envs/pytorch_conda/lib/python3.8/site-packages/wandb/sdk/wandb_manager.py", line 151, in __init__
    self._service_connect()
  File "/home2/surya_ravindra/miniconda3/envs/pytorch_conda/lib/python3.8/site-packages/wandb/sdk/wandb_manager.py", line 125, in _service_connect
    raise ManagerConnectionRefusedError(message)
wandb.sdk.wandb_manager.ManagerConnectionRefusedError: Connection to wandb service failed: [Errno 111] Connection refused. 

2024-03-07 08:50:14 ERROR Traceback (most recent call last):
  File "/home2/surya_ravindra/miniconda3/envs/pytorch_conda/lib/python3.8/site-packages/wandb/sdk/wandb_manager.py", line 116, in _service_connect
    svc_iface._svc_connect(port=port)
  File "/home2/surya_ravindra/miniconda3/envs/pytorch_conda/lib/python3.8/site-packages/wandb/sdk/service/service_sock.py", line 30, in _svc_connect
    self._sock_client.connect(port=port)
  File "/home2/surya_ravindra/miniconda3/envs/pytorch_conda/lib/python3.8/site-packages/wandb/sdk/lib/sock_client.py", line 102, in connect
    s.connect(("localhost", port))
ConnectionRefusedError: [Errno 111] Connection refused

During handling of the above exception, another exception occurred:

Traceback (most recent call last):
  File "/home2/surya_ravindra/miniconda3/envs/pytorch_conda/lib/python3.8/site-packages/wandb/cli/cli.py", line 105, in wrapper
    return func(*args, **kwargs)
  File "/home2/surya_ravindra/miniconda3/envs/pytorch_conda/lib/python3.8/site-packages/wandb/cli/cli.py", line 244, in login
    wandb.setup(settings=login_settings)
  File "/home2/surya_ravindra/miniconda3/envs/pytorch_conda/lib/python3.8/site-packages/wandb/sdk/wandb_setup.py", line 327, in setup
    ret = _setup(settings=settings)
  File "/home2/surya_ravindra/miniconda3/envs/pytorch_conda/lib/python3.8/site-packages/wandb/sdk/wandb_setup.py", line 320, in _setup
    wl = _WandbSetup(settings=settings)
  File "/home2/surya_ravindra/miniconda3/envs/pytorch_conda/lib/python3.8/site-packages/wandb/sdk/wandb_setup.py", line 303, in __init__
    _WandbSetup._instance = _WandbSetup__WandbSetup(settings=settings, pid=pid)
  File "/home2/surya_ravindra/miniconda3/envs/pytorch_conda/lib/python3.8/site-packages/wandb/sdk/wandb_setup.py", line 114, in __init__
    self._setup()
  File "/home2/surya_ravindra/miniconda3/envs/pytorch_conda/lib/python3.8/site-packages/wandb/sdk/wandb_setup.py", line 250, in _setup
    self._setup_manager()
  File "/home2/surya_ravindra/miniconda3/envs/pytorch_conda/lib/python3.8/site-packages/wandb/sdk/wandb_setup.py", line 277, in _setup_manager
    self._manager = wandb_manager._Manager(settings=self._settings)
  File "/home2/surya_ravindra/miniconda3/envs/pytorch_conda/lib/python3.8/site-packages/wandb/sdk/wandb_manager.py", line 153, in __init__
    wandb._sentry.reraise(e)
  File "/home2/surya_ravindra/miniconda3/envs/pytorch_conda/lib/python3.8/site-packages/wandb/analytics/sentry.py", line 154, in reraise
    raise exc.with_traceback(sys.exc_info()[2])
  File "/home2/surya_ravindra/miniconda3/envs/pytorch_conda/lib/python3.8/site-packages/wandb/sdk/wandb_manager.py", line 151, in __init__
    self._service_connect()
  File "/home2/surya_ravindra/miniconda3/envs/pytorch_conda/lib/python3.8/site-packages/wandb/sdk/wandb_manager.py", line 125, in _service_connect
    raise ManagerConnectionRefusedError(message)
wandb.sdk.wandb_manager.ManagerConnectionRefusedError: Connection to wandb service failed: [Errno 111] Connection refused. 

